Workbook

Sheet DashBoard
A1: Distributor | B1: BAUKO (213SPA)
A3: Rótulos de Linha | B3: Contagem de Code
A4: 714 - Arm | B4: 69
A5: 716 - Bucket | B5: 20
A6: A1T - Muffler | B6: 18
A7: H17 - Arm Cylinder | B7: 14
A8: 551 - Operator's Cab | B8: 9
A9: 450 - A/C | B9: 7
A10: 984 - Acessory / Others | B10: 7
A11: RX0 - Control valve | B11: 6
A12: D00 - Electric system | B12: 6
A13: 711 - Boom | B13: 6
A14: 301 - Track frame | B14: 5
A15: 6A0 - Hydraulic piping | B15: 4
... A28: A90 - Turbocharger | B28: 1
A29: (vazio)
A30: Total Geral | B30: 196

Sheet DB Description
A1: DB Code | B1: DB Nome
A2: 213I | B2: Mason
A3: 213PAE | B3: Mason
A4: 213SPA | B4: Bauko
A5: 213SPB | B5: Bauko
A6: 213SPC | B6: Bauko
A7: 213ESD | B7: Bauko
A8: 213GOC | B8: DCCO
A9: 2131D | B9: Noroeste
A10: 213BAB | B10: FW
A11: 213PEA | B11: FW
A12: 213CEB | B12: DCDN
... A19: 213ESC | B19: Florest
A20: 9447 | B20: CTK
A21: 213RSB | B21: MANTOMAC-CHA (213SCA)
A22: 213SCB | B22: MANTOMAC-CHA (213SCA)
A23: 213RSC | B23: VAMOS (2131F)

Sheet KBI (All) - SORT
A1: Report ID | B1: Title | C1: Full Model | D1: Serial Number | E1: CodeComponent | F1: Failure | G1: Additional Failure Description | H1: Parent Case | I1: Failure SMR | J1: Active Stage | K1: Failure2 | L1: Machine | M1: Machine2 | N1: Delivery | O1: Failed Part Number | P1: Failed Part Name | Q1: Component Name | R1: Phenomenon Name | S1: Plant | T1: Current Queue | U1: Status Reason | V1: Created | W1: Distributor | X1: Subsidiary | Y1: Issue2 | Z1: Additional Notes(Request) | AA1: Distributor Contact | AB1: Filial DB code | AC1: Filial DB NAME | AD1: LT DB | AE1: FY | AF1: YEAR
A2: KBISC202205531 | B2: PC130LC-10M0, CAB ASS'Y GROUP, RETROVISOR, WRONG/MISSING PART, SEM O ESPELHO RETROVISOR | C2: PC130LC-10M0 | D2: B20013 | E2: 551 - Operator's Cab | F2: Glass | G2: SEM O ESPELHO RETROVISOR | I2: 4 | J2: Sub.Received | K2: 44655 | M2: 44641 | O2: 2A5-54-13421 | P2: RETROVISOR | Q2: CAB ASS'Y GROUP | R2: WRONG/MISSING PART | S2: KDB (Plant) (51) | T2: KBI - Construction Service | U2: In Process | V2: 44683 | W2: MANTOMAC-CHA (213SCA) | X2: KBI (9447) | Y2: 44683 | Z2: EQUIPAMENTO NOVO. | AA2: Luciana Lumbieri | AB2: 213RSB | AC2: =INDEX('DB Description'!$A$1:$B$23,MATCH(Tabela2[[#This Row],[Filial DB code]],'DB Description'!A:A,),2) -> MANTOMAC-CHA (213SCA) | AD2: =Tabela2[[#This Row],[Issue2]]-Tabela2[[#This Row],[Failure2]] -> 28 | AE2: ="FY"&IF(MONTH(Y2)>=4,YEAR(Y2),YEAR(Y2)-1) -> FY2022 | AF2: =YEAR(Tabela2[[#This Row],[Issue2]]) -> 2022
A3: KBIPR202205527 | B3: PC130LC-10M0, OTHERS, WEIGHT, DEFECTIVE APPEARANCE, FALHA NA PINTURA E DESALINHAMENTO DO CON | C3: PC130LC-10M0 | D3: B20003 | E3: 000 - Machine | F3: Painting | G3: FALHA NA PINTURA E DESALINHAMENTO DO CON | I3: 29.7 | J3: Plant.QA Approved | K3: 44659 | M3: 44620 | N3: 44659 | O3: 204-46-B1010 | P3: WEIGHT | Q3: OTHERS | R3: DEFECTIVE APPEARANCE | S3: KDB (Plant) (51) | T3: KDB - Quality Assurance | U3: In Process | V3: 44684 | W3: VIANMAQ (213PRB) | X3: KBI (9447) | Y3: 44684 | Z3: CLIENTE POSSUI 3 MÁQUINAS. | AA3: Eduardo Lima | AB3: 213PRB | AC3: =INDEX('DB Description'!$A$1:$B$23,MATCH(Tabela2[[#This Row],[Filial DB code]],'DB Description'!A:A,),2) -> Vianmaq | AD3: =Tabela2[[#This Row],[Issue2]]-Tabela2[[#This Row],[Failure2]] -> 25 | AE3: ="FY"&IF(MONTH(Y3)>=4,YEAR(Y3),YEAR(Y3)-1) -> FY2022 | AF3: =YEAR(Tabela2[[#This Row],[Issue2]]) -> 2022
A4: KBIPE202205504 | B4: PC130LC-10M0, AIR SYSTEM, Caatiba, BA, WRONG/MISSING PART, Falta retencao de particulado | C4: PC130LC-10M0 | D4: B20014 | E4: 6A0 - Hydraulic piping | F4: Hose leak | G4: Falta retencao de particulado | I4: 8 | J4: Plant.QA Approved | K4: 44679 | M4: 44643 | O4: 204-03-71411 | P4: Caatiba, BA | Q4: AIR SYSTEM | R4: WRONG/MISSING PART | S4: KDB (Plant) (51) | T4: KDB - Quality Assurance | U4: In Process | V4: 44683 | W4: F.W.MAQUINAS (213PEA) | X4: KBI (9447) | Y4: 44719 | Z4: Equipamento chegou de fabrica sem o item especificado, provavelmente sobrou na hora da montagem, gentileza averiguar internamente o motivo da falta | AA4: Marcos Santos | AB4: 213BAB | AC4: =INDEX('DB Description'!$A$1:$B$23,MATCH(Tabela2[[#This Row],[Filial DB code]],'DB Description'!A:A,),2) -> FW | AD4: =Tabela2[[#This Row],[Issue2]]-Tabela2[[#This Row],[Failure2]] -> 40 | AE4: ="FY"&IF(MONTH(Y4)>=4,YEAR(Y4),YEAR(Y4)-1) -> FY2022 | AF4: =YEAR(Tabela2[[#This Row],[Issue2]]) -> 2022
A5: KBISC202206572 | B5: PC130LC-10M0, MACHINE, ., DEFECTIVE APPEARANCE, EQUIPAMENTO COM VARIOS DEFEITOS ESTETICO | C5: PC130LC-10M0 | D5: B20059 | E5: 000 - Machine | F5: Painting | G5: EQUIPAMENTO COM VARIOS DEFEITOS ESTETICO | I5: 5 | J5: Closed | K5: 44705 | L5: 44706 | M5: 44692 | O5: . | P5: . | Q5: MACHINE | R5: DEFECTIVE APPEARANCE | S5: KDB (Plant) (51) | U5: Completed | V5: 44733 | W5: MANTOMAC-CHA (213SCA) | X5: KBI (9447) | Y5: 44733 | Z5: Por fim, graças ao trabalho do Distribuidor para corrigir as falhas aparentes no recebimento do equipamento novo, o cliente final recebeu seu equipamento e por enquanto não houve reclamações sobre os problemas acima mencionados. Porém o equipamento atrasou em 2 dias ser entregue ao cliente devido os reparos que foram necessários serem executados. | AA5: Jonatas Kammer | AB5: 213SCB | AC5: =INDEX('DB Description'!$A$1:$B$23,MATCH(Tabela2[[#This Row],[Filial DB code]],'DB Description'!A:A,),2) -> MANTOMAC-CHA (213SCA) | AD5: =Tabela2[[#This Row],[Issue2]]-Tabela2[[#This Row],[Failure2]] -> 28 | AE5: ="FY"&IF(MONTH(Y5)>=4,YEAR(Y5),YEAR(Y5)-1) -> FY2022 | AF5: =YEAR(Tabela2[[#This Row],[Issue2]]) -> 2022
A6: KBISC202206578 | B6: PC130LC-10M0, MACHINE, 0, DEFECTIVE APPEARANCE, EQUIPAMENTO COM VARIOS DEFEITOS NA ESTET | C6: PC130LC-10M0 | D6: B20056 | E6: 000 - Machine | F6: Painting | G6: EQUIPAMENTO COM VARIOS DEFEITOS NA ESTET | I6: 4 | J6: Closed | K6: 44706 | L6: 44707 | M6: 44683 | N6: 44713 | O6: 0 | P6: 0 | Q6: MACHINE | R6: DEFECTIVE APPEARANCE | S6: KDB (Plant) (51) | U6: Completed | V6: 44734 | W6: MANTOMAC-CHA (213SCA) | X6: KBI (9447) | Y6: 44734 | Z6: Após os ajustes acima mencionados, o equipamento ficou em boas condições para ser entregue ao cliente final, que não reclamou de nada que referente aos defeitos encontrados e acima mencionados. Devido aos reparos que necessitaram correção, o equipamento foi entregue ao cliente final com 1 dia de atraso perante o combinado. | AA6: Jonatas Kammer | AB6: 213SCB | AC6: =INDEX('DB Description'!$A$1:$B$23,MATCH(Tabela2[[#This Row],[Filial DB code]],'DB Description'!A:A,),2) -> MANTOMAC-CHA (213SCA) | AD6: =Tabela2[[#This Row],[Issue2]]-Tabela2[[#This Row],[Failure2]] -> 28 | AE6: ="FY"&IF(MONTH(Y6)>=4,YEAR(Y6),YEAR(Y6)-1) -> FY2022 | AF6: =YEAR(Tabela2[[#This Row],[Issue2]]) -> 2022
A7: KBIMB202207553 | B7: PC130LC-10M0, HYDRAULIC CONTROL VALVE, ORING, ENTER/LEAKS, Vazamento de óleo na mangueira do SwiveL | C7: PC130LC-10M0 | D7: B20049 | E7: 6A0 - Hydraulic piping | F7: Hose leak | G7: Vazamento de óleo na mangueira do SwiveL | I7: 13 | J7: Plant.Confirmed | K7: 44751 | L7: 44753 | M7: 44673 | O7: 02896-11015 | P7: ORING | Q7: HYDRAULIC CONTROL VALVE | R7: ENTER/LEAKS | S7: KDB (Plant) (51) | T7: KDB - Quality Assurance | U7: In Process | V7: 44756 | W7: Mason (213I) | X7: KBI (9447) | Y7: 44767 | Z7: Equipamento veio de fábrica com as conexões da mangueiras do Swivel lado esquerdo frouxas. Efetuamos o atendimento, resolvendo o problema. | AA7: Higor Alves | AB7: 213MGC | AC7: =INDEX('DB Description'!$A$1:$B$23,MATCH(Tabela2[[#This Row],[Filial DB code]],'DB Description'!A:A,),2) -> Mason | AD7: =Tabela2[[#This Row],[Issue2]]-Tabela2[[#This Row],[Failure2]] -> 16 | AE7: ="FY"&IF(MONTH(Y7)>=4,YEAR(Y7),YEAR(Y7)-1) -> FY2022 | AF7: =YEAR(Tabela2[[#This Row],[Issue2]]) -> 2022
A8: KBI9A202207556 | B8: PC130LC-10M0, HYDRAULIC CYLINDER, Cilindro do Braço, ENTER/LEAKS, B20036 | C8: PC130LC-10M0 | D8: B20036 | E8: H17 - Arm Cylinder | F8: Vazamento cilindro do braço | G8: B20036 | I8: 438 | J8: Plant.QA Approved | K8: 44767 | M8: 44662 | N8: 44701 | O8: 707-G1-X7160 | P8: Cilindro do Braço | Q8: HYDRAULIC CYLINDER | R8: ENTER/LEAKS | S8: KDB (Plant) (51) | T8: KDB - Quality Assurance | U8: In Process | V8: 44768 | W8: DCCO (213GOC) | X8: KBI (9447) | Y8: 44768 | Z8: Essa é a primeira falha ocorrida em nossa região neste modelo de equipamento. A princípio não há evidências de mau uso que possam ter ocasionado na falha identificada pelo cliente. | AA8: Pedro Vaz | AB8: 213GOC | AC8: =INDEX('DB Description'!$A$1:$B$23,MATCH(Tabela2[[#This Row],[Filial DB code]],'DB Description'!A:A,),2) -> DCCO | AD8: =Tabela2[[#This Row],[Issue2]]-Tabela2[[#This Row],[Failure2]] -> 1 | AE8: ="FY"&IF(MONTH(Y8)>=4,YEAR(Y8),YEAR(Y8)-1) -> FY2022 | AF8: =YEAR(Tabela2[[#This Row],[Issue2]]) -> 2022
A9: KBISP202208580 | B9: PC130LC-10M0, ENGINE ASSY, muffler, DEFECTIVE APPEARANCE, | C9: PC130LC-10M0 | D9: B20033 | E9: A1T - Muffler | F9: Abnormal noise on muffler (before countermeasure) | G9: =Tabela2[[#This Row],[Failed Part Name]] -> muffler | I9: 251 | J9: Closed | K9: 44768 | L9: 44768 | M9: 44650 | N9: 44670 | O9: 6271-11-5230 | P9: muffler | Q9: ENGINE ASSY | R9: DEFECTIVE APPEARANCE | S9: KDB (Plant) (51) | U9: Completed | V9: 44784 | W9: BAUKO (213SPA) | X9: KBI (9447) | Y9: 44784 | Z9: MAQUINA PERTENCE A BAUKO MAQUINAS (RENTAL) AO FAZER A INSPEÇÃO DE 250 HORAS PARA LIBERAÇÃO PARA NO CLIENTE FOI CONSTATADO O RUIDO ORIUNDO DO SILENCIOSO SEMELHANTE AO OCORRIDO NAS PC130-8, MAQUINA ATUALMENTE ESTA ALUGADA PARA O CLIENTE HANS JOSEFE. | AA9: Gabriel Augusto | AB9: 213ESD | AC9: =INDEX('DB Description'!$A$1:$B$23,MATCH(Tabela2[[#This Row],[Filial DB code]],'DB Description'!A:A,),2) -> Bauko | AD9: =Tabela2[[#This Row],[Issue2]]-Tabela2[[#This Row],[Failure2]] -> 16 | AE9: ="FY"&IF(MONTH(Y9)>=4,YEAR(Y9),YEAR(Y9)-1) -> FY2022 | AF9: =YEAR(Tabela2[[#This Row],[Issue2]]) -> 2022
A10: KBI1D202208515 | B10: PC130LC-10M0, BUCKET(H/E BACKHOE), Dente de Aço, BROKEN, | C10: PC130LC-10M0 | D10: B20040 | E10: 716 - Bucket | F10: Bucket clearance | G10: =Tabela2[[#This Row],[Failed Part Name]] -> Dente de Aço | I10: 117 | J10: Sub.Submitted | K10: 44729 | L10: 44790 | M10: 44662 | O10: KH20S | P10: Dente de Aço | Q10: BUCKET(H/E BACKHOE) | R10: BROKEN | S10: KDB (Plant) (51) | T10: <Guilherme Augusto Macedo> | U10: In Process | V10: 44791 | W10: NOROESTE (2131D) | X10: KBI (9447) | Y10: 44791 | Z10: Primeiro equipamento PC130, vendido na regiao norte. | AA10: Bruno Rocha | AB10: 2131D | AC10: =INDEX('DB Description'!$A$1:$B$23,MATCH(Tabela2[[#This Row],[Filial DB code]],'DB Description'!A:A,),2) -> Noroeste | AD10: =Tabela2[[#This Row],[Issue2]]-Tabela2[[#This Row],[Failure2]] -> 62 | AE10: ="FY"&IF(MONTH(Y10)>=4,YEAR(Y10),YEAR(Y10)-1) -> FY2022 | AF10: =YEAR(Tabela2[[#This Row],[Issue2]]) -> 2022
A11: KBISC202208629 | B11: PC130LC-10M0, FUEL TANK GROUP, FILTRO SEPARADOR, ENTER/LEAKS, TRINCA NO FILTRO SEPARADOR DO DIESEL | C11: PC130LC-10M0 | D11: B20056 | E11: 602 - Hydraulic filter | G11: TRINCA NO FILTRO SEPARADOR DO DIESEL | I11: 66 | J11: Plant.Confirmed | K11: 44740 | L11: 44804 | M11: 44683 | N11: 44713 | O11: 600-311-9921 | P11: FILTRO SEPARADOR | Q11: FUEL TANK GROUP | R11: ENTER/LEAKS | S11: KDB (Plant) (51) | T11: KDB - Quality Assurance | U11: In Process | V11: 44804 | W11: MANTOMAC-CHA (213SCA) | X11: KBI (9447) | Y11: 44804 | AA11: Jonatas Kammer | AB11: 213SCB | AC11: =INDEX('DB Description'!$A$1:$B$23,MATCH(Tabela2[[#This Row],[Filial DB code]],'DB Description'!A:A,),2) -> MANTOMAC-CHA (213SCA) | AD11: =Tabela2[[#This Row],[Issue2]]-Tabela2[[#This Row],[Failure2]] -> 64 | AE11: ="FY"&IF(MONTH(Y11)>=4,YEAR(Y11),YEAR(Y11)-1) -> FY2022 | AF11: =YEAR(Tabela2[[#This Row],[Issue2]]) -> 2022
A12: KBISP202209501 | B12: PC130LC-10M0, RADIATOR GROUP, NA, HIGH/LOW LEVEL, | C12: PC130LC-10M0 | D12: B20095 | E12: 551 - Operator's Cab | F12: Glass | G12: =Tabela2[[#This Row],[Failed Part Name]] -> NA | I12: 70 | J12: Plant.Confirmed | K12: 44789 | L12: 44802 | M12: 44734 | N12: 44776 | O12: NA | P12: NA | Q12: RADIATOR GROUP | R12: HIGH/LOW LEVEL | S12: KDB (Plant) (51) | T12: KDB - Quality Assurance | U12: In Process | V12: 44805 | W12: BAUKO (213SPA) | X12: KBI (9447) | Y12: 44805 | Z12: CASO RETOME O VAZAMENTO, ENTRAR EM CONTATO COM A BAUKO. FOI REAPERTADO TODAS AS PRESILHAS DA LINHA DE ARREFECIMENTO, COMPLETADO O LIQUIDO ARREFECIMENTO E O EQUIPAMENTO VOLTOU A OPERAR SEM VAZAMENTOS. | AA12: Rafaella Ribeiro | AB12: 213SPC | AC12: =INDEX('DB Description'!$A$1:$B$23,MATCH(Tabela2[[#This Row],[Filial DB code]],'DB Description'!A:A,),2) -> Bauko | AD12: =Tabela2[[#This Row],[Issue2]]-Tabela2[[#This Row],[Failure2]] -> 16 | AE12: ="FY"&IF(MONTH(Y12)>=4,YEAR(Y12),YEAR(Y12)-1) -> FY2022 | AF12: =YEAR(Tabela2[[#This Row],[Issue2]]) -> 2022
A13: KBISC202209502 | B13: PC130LC-10M0, RADIATOR GROUP, NET, MALFUNCTION, FALTA DA TELA DE PROTEÇAO DOS RADIADORES | C13: PC130LC-10M0 | D13: B20013 | E13: 301 - Track frame | F13: Missing part | G13: FALTA DA TELA DE PROTEÇAO DOS RADIADORES | I13: 468 | J13: Plant.Confirmed | K13: 44799 | M13: 44641 | N13: 44663 | O13: 204-03-71411 | P13: NET | Q13: RADIATOR GROUP | R13: MALFUNCTION | S13: KDB (Plant) (51) | T13: KDB - Quality Assurance | U13: In Process | V13: 44810 | W13: MANTOMAC-CHA (213SCA) | X13: KBI (9447) | Y13: 44810 | Z13: EQUIPAMENTO NOVO COM AS MANUTENÇOES EM DIA. | AA13: Luciana Lumbieri | AB13: 213RSB | AC13: =INDEX('DB Description'!$A$1:$B$23,MATCH(Tabela2[[#This Row],[Filial DB code]],'DB Description'!A:A,),2) -> MANTOMAC-CHA (213SCA) | AD13: =Tabela2[[#This Row],[Issue2]]-Tabela2[[#This Row],[Failure2]] -> 11 | AE13: ="FY"&IF(MONTH(Y13)>=4,YEAR(Y13),YEAR(Y13)-1) -> FY2022 | AF13: =YEAR(Tabela2[[#This Row],[Issue2]]) -> 2022
A14: KBISP202209505 | B14: PC130LC-10M0, ACCESSORY & PARTS, Cover, WRONG/MISSING PART, | C14: PC130LC-10M0 | D14: B20089 | E14: 716 - Bucket | F14: Bucket clearance | G14: =Tabela2[[#This Row],[Failed Part Name]] -> Cover | I14: 5 | J14: Plant.Confirmed | K14: 44781 | L14: 44803 | M14: 44733 | O14: 203-46-56160 | P14: Cover | Q14: ACCESSORY & PARTS | R14: WRONG/MISSING PART | S14: KDB (Plant) (51) | T14: KDB - Quality Assurance | U14: In Process | V14: 44813 | W14: BAUKO (213SPA) | X14: KBI (9447) | Y14: 44813 | AA14: Luis Siqueira | AB14: 213SPA | AC14: =INDEX('DB Description'!$A$1:$B$23,MATCH(Tabela2[[#This Row],[Filial DB code]],'DB Description'!A:A,),2) -> Bauko | AD14: =Tabela2[[#This Row],[Issue2]]-Tabela2[[#This Row],[Failure2]] -> 32 | AE14: ="FY"&IF(MONTH(Y14)>=4,YEAR(Y14),YEAR(Y14)-1) -> FY2022 | AF14: =YEAR(Tabela2[[#This Row],[Issue2]]) -> 2022
A15: KBISC202209504 | B15: PC130LC-10M0, AIR CONDITIONER, SUPORTE CONDENSADOR, BROKEN, QUEBRA DO SUPORTE DO CONDENSADOR | C15: PC130LC-10M0 | D15: B20051 | E15: 450 - A/C | F15: Condensor support crack | G15: QUEBRA DO SUPORTE DO CONDENSADOR | I15: 568 | J15: Plant.Confirmed | K15: 44813 | M15: 44677 | N15: 44694 | O15: 204-03-72111 | P15: SUPORTE CONDENSADOR | Q15: AIR CONDITIONER | R15: BROKEN | S15: KDB (Plant) (51) | T15: KDB - Quality Assurance | U15: In Process | V15: 44816 | W15: MANTOMAC-CHA (213SCA) | X15: KBI (9447) | Y15: 44816 | Z15: Obs: Já foi notado em todos os equipamentos recebidos novos na Mantomac deste modelo (PC130LC-10M0) que este suporte do condensador possui folga nas dobradiças, e com o trabalhar do equipamento há o balançar/trepidar de toda a estrutura (suporte do condensador e condensador). Necessário avaliar internamente. | AA15: Jonatas Kammer | AB15: 213SCB | AC15: =INDEX('DB Description'!$A$1:$B$23,MATCH(Tabela2[[#This Row],[Filial DB code]],'DB Description'!A:A,),2) -> MANTOMAC-CHA (213SCA) | AD15: =Tabela2[[#This Row],[Issue2]]-Tabela2[[#This Row],[Failure2]] -> 3 | AE15: ="FY"&IF(MONTH(Y15)>=4,YEAR(Y15),YEAR(Y15)-1) -> FY2022 | AF15: =YEAR(Tabela2[[#This Row],[Issue2]]) -> 2022
A16: KBISC202209510 | B16: PC130LC-10M0, AIR CONDITIONER, TRAVA SUPORTE CONDENSADOR, SERVICEABILITY, FOLGA NA TRAVA DO SUPORTE DO CONDENSADOR | C16: PC130LC-10M0 | D16: B20056 | E16: 450 - A/C | F16: Condensor support crack | G16: FOLGA NA TRAVA DO SUPORTE DO CONDENSADOR | I16: 231 | J16: Sub.Received | K16: 44804 | L16: 44804 | M16: 44683 | N16: 44713 | O16: 2A3-03-12850 | P16: TRAVA SUPORTE CONDENSADOR | Q16: AIR CONDITIONER | R16: SERVICEABILITY | S16: KDB (Plant) (51) | T16: KBI - Construction Service | U16: In Process | V16: 44818 | W16: MANTOMAC-CHA (213SCA) | X16: KBI (9447) | Y16: 44818 | Z16: Favor consultar a TSI: KBISC202209504 que trás a falha semelhante, porém neste caso houve a quebra da solda da dobradiça deste suporte do motor. Equipamento do mesmo modelo: PC130LC-10M0 e série: B20051. | AA16: Jonatas Kammer | AB16: 213SCB | AC16: =INDEX('DB Description'!$A$1:$B$23,MATCH(Tabela2[[#This Row],[Filial DB code]],'DB Description'!A:A,),2) -> MANTOMAC-CHA (213SCA) | AD16: =Tabela2[[#This Row],[Issue2]]-Tabela2[[#This Row],[Failure2]] -> 14 | AE16: ="FY"&IF(MONTH(Y16)>=4,YEAR(Y16),YEAR(Y16)-1) -> FY2022 | AF16: =YEAR(Tabela2[[#This Row],[Issue2]]) -> 2022
A17: KBISC202209512 | B17: PC130LC-10M0, AIR CONDITIONER, TRAVA SUPORTE CONDENSADOR, SERVICEABILITY, FOLGA NO SUPORTE DO CONDENSADOR | C17: PC130LC-10M0 | D17: B20080 | E17: 450 - A/C | F17: Condensor support crack | G17: FOLGA NO SUPORTE DO CONDENSADOR | I17: 222 | J17: Sub.Received | K17: 44789 | L17: 44789 | M17: 44715 | N17: 44734 | O17: 2A3-03-12850 | P17: TRAVA SUPORTE CONDENSADOR | Q17: AIR CONDITIONER | R17: SERVICEABILITY | S17: KDB (Plant) (51) | T17: KBI - Construction Service | U17: In Process | V17: 44820 | W17: MANTOMAC-CHA (213SCA) | X17: KBI (9447) | Y17: 44820 | Z17: Problema já encontrado em mais equipamentos deste modelo. | AA17: Jonatas Kammer | AB17: 213SCB | AC17: =INDEX('DB Description'!$A$1:$B$23,MATCH(Tabela2[[#This Row],[Filial DB code]],'DB Description'!A:A,),2) -> MANTOMAC-CHA (213SCA) | AD17: =Tabela2[[#This Row],[Issue2]]-Tabela2[[#This Row],[Failure2]] -> 31 | AE17: ="FY"&IF(MONTH(Y17)>=4,YEAR(Y17),YEAR(Y17)-1) -> FY2022 | AF17: =YEAR(Tabela2[[#This Row],[Issue2]]) -> 2022
A18: KBISP202209507 | B18: PC130LC-10M0, RADIATOR GROUP, NIVEL BAIXO ANTICONGELANTE, HIGH/LOW LEVEL, NIVEL BAIXO LIQ ARREFECIMENTO NO RESERVA | C18: PC130LC-10M0 | D18: B20116 | E18: 450 - A/C | F18: Condensor support crack | G18: NIVEL BAIXO LIQ ARREFECIMENTO NO RESERVA | H18: PC130LC-10M0, TC COOLER & OIL COOLER GROUP, NIVEL BAIXO ANTICONGELANTE, HIGH/LOW LEVEL, | I18: 116 | J18: Plant.Confirmed | K18: 44819 | L18: 44819 | M18: 44762 | N18: 44797 | O18: 600-411-1113 | P18: NIVEL BAIXO ANTICONGELANTE | Q18: RADIATOR GROUP | R18: HIGH/LOW LEVEL | S18: KDB (Plant) (51) | T18: KDB - Quality Assurance | U18: In Process | V18: 44820 | W18: BAUKO (213SPA) | X18: KBI (9447) | Y18: 44820 | AA18: Calvin Lee | AB18: 213SPB | AC18: =INDEX('DB Description'!$A$1:$B$23,MATCH(Tabela2[[#This Row],[Filial DB code]],'DB Description'!A:A,),2) -> Bauko | AD18: =Tabela2[[#This Row],[Issue2]]-Tabela2[[#This Row],[Failure2]] -> 1 | AE18: ="FY"&IF(MONTH(Y18)>=4,YEAR(Y18),YEAR(Y18)-1) -> FY2022 | AF18: =YEAR(Tabela2[[#This Row],[Issue2]]) -> 2022
A19: KBISP202209508 | B19: PC130LC-10M0, ACCESSORY & PARTS, PARAFUSO, DEFECTIVE ADJUSTMENT, | C19: PC130LC-10M0 | D19: B20144 | E19: 716 - Bucket | F19: Bucket clearance | G19: =Tabela2[[#This Row],[Failed Part Name]] -> PARAFUSO | I19: 4 | J19: Sub.Received | K19: 44819 | L19: 44819 | M19: 44797 | O19: 22B-32-21230 | P19: PARAFUSO | Q19: ACCESSORY & PARTS | R19: DEFECTIVE ADJUSTMENT | S19: KDB (Plant) (51) | T19: KBI - Construction Service | U19: In Process | V19: 44820 | W19: BAUKO (213SPA) | X19: KBI (9447) | Y19: 44820 | AA19: Luis Siqueira | AB19: 213SPA | AC19: =INDEX('DB Description'!$A$1:$B$23,MATCH(Tabela2[[#This Row],[Filial DB code]],'DB Description'!A:A,),2) -> Bauko | AD19: =Tabela2[[#This Row],[Issue2]]-Tabela2[[#This Row],[Failure2]] -> 1 | AE19: ="FY"&IF(MONTH(Y19)>=4,YEAR(Y19),YEAR(Y19)-1) -> FY2022 | AF19: =YEAR(Tabela2[[#This Row],[Issue2]]) -> 2022
A20: KBIMB202209516 | B20: PC130LC-10M0, ARM, Mangueira, ENTER/LEAKS, Vazamento mangueira braço lado direito | C20: PC130LC-10M0 | D20: B20136 | E20: 6A0 - Hydraulic piping | F20: Hose leak | G20: Vazamento mangueira braço lado direito | I20: 4 | J20: Plant.QA Approved | K20: 44796 | L20: 44796 | M20: 44789 | O20: 02756-20513 | P20: Mangueira | Q20: ARM | R20: ENTER/LEAKS | S20: KDB (Plant) (51) | T20: KDB - Quality Assurance | U20: In Process | V20: 44827 | W20: Mason (213I) | X20: KBI (9447) | Y20: 44827 | Z20: Cliente não ficou sabendo do ocorrido pois, foi detectado na chegada da máquina à Mason CTG. Os custos de serviços serão enviados à Komatsu para reembolso em garantia. | AA20: Leandro Leite | AB20: 213I | AC20: =INDEX('DB Description'!$A$1:$B$23,MATCH(Tabela2[[#This Row],[Filial DB code]],'DB Description'!A:A,),2) -> Mason | AD20: =Tabela2[[#This Row],[Issue2]]-Tabela2[[#This Row],[Failure2]] -> 31 | AE20: ="FY"&IF(MONTH(Y20)>=4,YEAR(Y20),YEAR(Y20)-1) -> FY2022 | AF20: =YEAR(Tabela2[[#This Row],[Issue2]]) -> 2022
A21: KBISP202209511 | B21: PC130LC-10M0, RADIATOR GROUP, ADAPTADOR, ENTER/LEAKS, | C21: PC130LC-10M0 | D21: B20117 | E21: 716 - Bucket | F21: Bucket clearance | G21: =Tabela2[[#This Row],[Failed Part Name]] -> ADAPTADOR | I21: 43 | J21: Plant.Confirmed | K21: 44823 | M21: 44764 | N21: 44823 | O21: 6208-51-5410 | P21: ADAPTADOR | Q21: RADIATOR GROUP | R21: ENTER/LEAKS | S21: KDB (Plant) (51) | T21: <Guilherme Augusto Macedo> | U21: Pending Request | V21: 44830 | W21: BAUKO (213SPA) | X21: KBI (9447) | Y21: 44830 | AA21: Luis Siqueira | AB21: 213SPA | AC21: =INDEX('DB Description'!$A$1:$B$23,MATCH(Tabela2[[#This Row],[Filial DB code]],'DB Description'!A:A,),2) -> Bauko | AD21: =Tabela2[[#This Row],[Issue2]]-Tabela2[[#This Row],[Failure2]] -> 7 | AE21: ="FY"&IF(MONTH(Y21)>=4,YEAR(Y21),YEAR(Y21)-1) -> FY2022 | AF21: =YEAR(Tabela2[[#This Row],[Issue2]]) -> 2022
A22: KBISP202209515 | B22: PC130LC-10M0, OPERATOR CAB & ROPS, SELO, ENTER/LEAKS, | C22: PC130LC-10M0 | D22: B20108 | E22: 6A0 - Hydraulic piping | F22: Hose leak | G22: =Tabela2[[#This Row],[Failed Part Name]] -> SELO | I22: 162 | J22: Sub.Received | K22: 44826 | M22: 44753 | O22: 20Y-53-11540 | P22: SELO | Q22: OPERATOR CAB & ROPS | R22: ENTER/LEAKS | S22: KDB (Plant) (51) | T22: KBI - Construction Service | U22: In Process | V22: 44831 | W22: BAUKO (213SPA) | X22: KBI (9447) | Y22: 44831 | AA22: Luis Siqueira | AB22: 213SPA | AC22: =INDEX('DB Description'!$A$1:$B$23,MATCH(Tabela2[[#This Row],[Filial DB code]],'DB Description'!A:A,),2) -> Bauko | AD22: =Tabela2[[#This Row],[Issue2]]-Tabela2[[#This Row],[Failure2]] -> 5 | AE22: ="FY"&IF(MONTH(Y22)>=4,YEAR(Y22),YEAR(Y22)-1) -> FY2022 | AF22: =YEAR(Tabela2[[#This Row],[Issue2]]) -> 2022
A23: KBISP202210500 | B23: PC130LC-10M0, OTHERS, CONJUNTO ESTEIRA, DEFECTIVE APPEARANCE, | C23: PC130LC-10M0 | D23: B20035 | E23: 301 - Track frame | F23: Track abnormal noise | G23: =Tabela2[[#This Row],[Failed Part Name]] -> CONJUNTO ESTEIRA | I23: 454 | J23: Closed | K23: 44832 | M23: 44651 | N23: 44658 | O23: 203-32-02482 | P23: CONJUNTO ESTEIRA | Q23: OTHERS | R23: DEFECTIVE APPEARANCE | S23: KDB (Plant) (51) | U23: Completed | V23: 44837 | W23: BAUKO (213SPA) | X23: KBI (9447) | Y23: 44837 | AA23: Luis Siqueira | AB23: 213SPA | AC23: =INDEX('DB Description'!$A$1:$B$23,MATCH(Tabela2[[#This Row],[Filial DB code]],'DB Description'!A:A,),2) -> Bauko | AD23: =Tabela2[[#This Row],[Issue2]]-Tabela2[[#This Row],[Failure2]] -> 5 | AE23: ="FY"&IF(MONTH(Y23)>=4,YEAR(Y23),YEAR(Y23)-1) -> FY2022 | AF23: =YEAR(Tabela2[[#This Row],[Issue2]]) -> 2022
A24: KBISP202210513 | B24: PC130LC-10M0, OTHERS, CONJUNTO ESTEIRA, DEFECTIVE APPEARANCE, | C24: PC130LC-10M0 | D24: B20092 | E24: 301 - Track frame | F24: Track abnormal noise | G24: =Tabela2[[#This Row],[Failed Part Name]] -> CONJUNTO ESTEIRA | I24: 22 | J24: Sub.Received | K24: 44841 | M24: 44734 | N24: 44817 | O24: 203-32-02482 | P24: CONJUNTO ESTEIRA | Q24: OTHERS | R24: DEFECTIVE APPEARANCE | S24: KDB (Plant) (51) | T24: KBI - Construction Service | U24: In Process | V24: 44853 | W24: BAUKO (213SPA) | X24: KBI (9447) | Y24: 44853 | AA24: Luis Siqueira | AB24: 213SPA | AC24: =INDEX('DB Description'!$A$1:$B$23,MATCH(Tabela2[[#This Row],[Filial DB code]],'DB Description'!A:A,),2) -> Bauko | AD24: =Tabela2[[#This Row],[Issue2]]-Tabela2[[#This Row],[Failure2]] -> 12 | AE24: ="FY"&IF(MONTH(Y24)>=4,YEAR(Y24),YEAR(Y24)-1) -> FY2022 | AF24: =YEAR(Tabela2[[#This Row],[Issue2]]) -> 2022
A25: KBISC202210519 | B25: PC130LC-10M0, ACCESSORY & PARTS, FECHADURA PORTA INSPEÇÃO, WRONG/MISSING PART, PERDA DA TRAVA DA PORTA DE INSPEÇÃO | C25: PC130LC-10M0 | D25: B20113 | E25: 301 - Track frame | F25: Track abnormal noise | G25: PERDA DA TRAVA DA PORTA DE INSPEÇÃO | I25: 212 | J25: Sub.Received | K25: 44833 | M25: 44762 | O25: 20Y-54-77160 | P25: FECHADURA PORTA INSPEÇÃO | Q25: ACCESSORY & PARTS | R25: WRONG/MISSING PART | S25: KDB (Plant) (51) | T25: KBI - Construction Service | U25: In Process | V25: 44858 | W25: MANTOMAC-CHA (213SCA) | X25: KBI (9447) | Y25: 44858 | AA25: Jonatas Kammer | AB25: 213SCB | AC25: =INDEX('DB Description'!$A$1:$B$23,MATCH(Tabela2[[#This Row],[Filial DB code]],'DB Description'!A:A,),2) -> MANTOMAC-CHA (213SCA) | AD25: =Tabela2[[#This Row],[Issue2]]-Tabela2[[#This Row],[Failure2]] -> 25 | AE25: ="FY"&IF(MONTH(Y25)>=4,YEAR(Y25),YEAR(Y25)-1) -> FY2022 | AF25: =YEAR(Tabela2[[#This Row],[Issue2]]) -> 2022
A26: KBI9A202209504 | B26: PC130LC-10M0, REVOLVING FRAME,COUNTER WEIGHT, Espuma, DEFECTIVE ADJUSTMENT, B20042 | C26: PC130LC-10M0 | D26: B20042 | E26: 6A0 - Hydraulic piping | F26: Hose leak | G26: =Tabela2[[#This Row],[Failed Part Name]] -> Espuma | I26: 532 | J26: Sub.Received | K26: 44826 | M26: 44662 | N26: 44762 | O26: 203-54-17270 | P26: Espuma | Q26: REVOLVING FRAME,COUNTER WEIGHT | R26: DEFECTIVE ADJUSTMENT | S26: KDB (Plant) (51) | T26: KBI - Construction Service | U26: In Process | V26: 44832 | W26: DCCO (213GOC) | X26: KBI (9447) | Y26: 44860 | Z26: Essa e a primeira falha ocorrida em nossa região. A principio e necessário fazer a fixação da espuma ou fazer a sua substituição | AA26: CLAYTON SOUSA | AB26: 213GOC | AC26: =INDEX('DB Description'!$A$1:$B$23,MATCH(Tabela2[[#This Row],[Filial DB code]],'DB Description'!A:A,),2) -> DCCO | AD26: =Tabela2[[#This Row],[Issue2]]-Tabela2[[#This Row],[Failure2]] -> 34 | AE26: ="FY"&IF(MONTH(Y26)>=4,YEAR(Y26),YEAR(Y26)-1) -> FY2022 | AF26: =YEAR(Tabela2[[#This Row],[Issue2]]) -> 2022
A27: KBISC202211500 | B27: PC130LC-10M0, AIR CONDITIONER, HOSE, MALFUNCTION, AR CONDICIONADO NAO ESTA FUNCIONANDO | C27: PC130LC-10M0 | D27: B20154 | E27: 450 - A/C | F27: Condensor support crack | G27: AR CONDICIONADO NAO ESTA FUNCIONANDO | I27: 16 | J27: Plant.Confirmed | K27: 44837 | L27: 44862 | M27: 44816 | N27: 44837 | O27: 204-979-7121 | P27: HOSE | Q27: AIR CONDITIONER | R27: MALFUNCTION | S27: KDB (Plant) (51) | T27: KDB - Quality Assurance | U27: In Process | V27: 44868 | W27: MANTOMAC-CHA (213SCA) | X27: KBI (9447) | Y27: 44868 | Z27: EQUIPAMENTO NOVO. CLIENTE FECHOU PLANO PMP 250 – 2000 HRS. | AA27: Luciana Lumbieri | AB27: 213RSB | AC27: =INDEX('DB Description'!$A$1:$B$23,MATCH(Tabela2[[#This Row],[Filial DB code]],'DB Description'!A:A,),2) -> MANTOMAC-CHA (213SCA) | AD27: =Tabela2[[#This Row],[Issue2]]-Tabela2[[#This Row],[Failure2]] -> 31 | AE27: ="FY"&IF(MONTH(Y27)>=4,YEAR(Y27),YEAR(Y27)-1) -> FY2022 | AF27: =YEAR(Tabela2[[#This Row],[Issue2]]) -> 2022
A28: KBISP202210514 | B28: PC130LC-10M0, TRAVEL MOTOR ASSY, MOTOR DE DESLOCAMENTO, DEFECTIVE APPEARANCE, DIFERNÇA VELOC. MOTORES DE DESLOCAMENTO | C28: PC130LC-10M0 | D28: B20108 | E28: 301 - Track frame | F28: Track abnormal noise | G28: DIFERNÇA VELOC. MOTORES DE DESLOCAMENTO | I28: 317 | J28: Sub.Received | K28: 44852 | M28: 44753 | O28: TZ710D200000-B | P28: MOTOR DE DESLOCAMENTO | Q28: TRAVEL MOTOR ASSY | R28: DEFECTIVE APPEARANCE | S28: KDB (Plant) (51) | T28: KBI - Construction Service | U28: In Process | V28: 44853 | W28: BAUKO (213SPA) | X28: KBI (9447) | Y28: 44873 | Z28: TÉCNICO REALIZOU SEGUNDA VISITA PARA TESTES NA DATA DE 28/10/2022 - REALIZADO INVERSÃO DAS VÁLVULAS DE ALÍVIO DOS MOTORES HIDRAULICOS, VERIFICADO SOLENÓIDES DA RÉGUA, TESTE DE FULGA NO MOTOR DE AMBOS OS LADOS, PRESSÃO DE STOLL DOS MOTORES 354KgF/cm. TODOS OS TESTES ESTÃO DENTRO DO PADRÃO, PORÉM MESMO ASSIM MÁQUINA CONTINUA DESVIANDO. | AA28: Calvin Lee | AB28: 213SPB | AC28: =INDEX('DB Description'!$A$1:$B$23,MATCH(Tabela2[[#This Row],[Filial DB code]],'DB Description'!A:A,),2) -> Bauko | AD28: =Tabela2[[#This Row],[Issue2]]-Tabela2[[#This Row],[Failure2]] -> 21 | AE28: ="FY"&IF(MONTH(Y28)>=4,YEAR(Y28),YEAR(Y28)-1) -> FY2022 | AF28: =YEAR(Tabela2[[#This Row],[Issue2]]) -> 2022
A29: KBISP202211503 | B29: PC130LC-10M0, ENGINE ASSY, VÁLVULA DRENO, ENTER/LEAKS, | C29: PC130LC-10M0 | D29: B20053 | E29: 6A0 - Hydraulic piping | F29: Hose leak | G29: =Tabela2[[#This Row],[Failed Part Name]] -> VÁLVULA DRENO | I29: 580 | J29: Sub.Submitted | K29: 44861 | L29: 44866 | M29: 44678 | N29: 44720 | O29: 6738-21-5610 | P29: VÁLVULA DRENO | Q29: ENGINE ASSY | R29: ENTER/LEAKS | S29: KDB (Plant) (51) | T29: <Guilherme Augusto Macedo> | U29: In Process | V29: 44873 | W29: BAUKO (213SPA) | X29: KBI (9447) | Y29: 44873 | AA29: Luis Siqueira | AB29: 213SPA | AC29: =INDEX('DB Description'!$A$1:$B$23,MATCH(Tabela2[[#This Row],[Filial DB code]],'DB Description'!A:A,),2) -> Bauko | AD29: =Tabela2[[#This Row],[Issue2]]-Tabela2[[#This Row],[Failure2]] -> 12 | AE29: ="FY"&IF(MONTH(Y29)>=4,YEAR(Y29),YEAR(Y29)-1) -> FY2022 | AF29: =YEAR(Tabela2[[#This Row],[Issue2]]) -> 2022
A30: KBISP202211505 | B30: PC130LC-10M0, BUCKET(H/E BACKHOE), Caçamba, BROKEN, | C30: PC130LC-10M0 | D30: B20026 | E30: 716 - Bucket | F30: Bucket clearance | G30: =Tabela2[[#This Row],[Failed Part Name]] -> Caçamba | I30: 977 | J30: Closed | K30: 44868 | M30: 44648 | N30: 44683 | O30: 203-70-B2010 | P30: Caçamba | Q30: BUCKET(H/E BACKHOE) | R30: BROKEN | S30: KDB (Plant) (51) | U30: Completed | V30: 44876 | W30: BAUKO (213SPA) | X30: KBI (9447) | Y30: 44876 | Z30: A PEÇA VEIO A FRATURAR POR REDUÇÃO NA ÁREA DE ESFORÇO, PROVENIENTE DA PROPAGAÇÃO DA TRINCA, MÁQUINA FALHOU APÓS 7 MESES DA ENTREGA TECNICA, EQUIPAMENTO COM BAIXO HORIMETRO E PRIMEIRA REVISÃO DE 500 HORAS FEITA COM O DISTRIBUIDOR BAUKO. | AA30: Gabriel Augusto | AB30: 213ESD | AC30: =INDEX('DB Description'!$A$1:$B$23,MATCH(Tabela2[[#This Row],[Filial DB code]],'DB Description'!A:A,),2) -> Bauko | AD30: =Tabela2[[#This Row],[Issue2]]-Tabela2[[#This Row],[Failure2]] -> 8 | AE30: ="FY"&IF(MONTH(Y30)>=4,YEAR(Y30),YEAR(Y30)-1) -> FY2022 | AF30: =YEAR(Tabela2[[#This Row],[Issue2]]) -> 2022
A31: KBISC202211504 | B31: PC130LC-10M0, ACCESSORY & PARTS, PARAFUSO, MALFUNCTION, PARAFUSO TRAVA DO PISTAO DO CILINDRO | C31: PC130LC-10M0 | D31: B20079 | E31: H17 - Arm cylinder | F31: Arm cylinder trim | G31: PARAFUSO TRAVA DO PISTAO DO CILINDRO | I31: 144 | J31: Sub.Received | K31: 44792 | L31: 44796 | M31: 44715 | N31: 44747 | O31: 01010-81435 | P31: PARAFUSO | Q31: ACCESSORY & PARTS | R31: MALFUNCTION | S31: KDB (Plant) (51) | T31: KBI - Construction Service | U31: In Process | V31: 44882 | W31: MANTOMAC-CHA (213SCA) | X31: KBI (9447) | Y31: 44882 | AA31: Jonatas Kammer | AB31: 213SCB | AC31: =INDEX('DB Description'!$A$1:$B$23,MATCH(Tabela2[[#This Row],[Filial DB code]],'DB Description'!A:A,),2) -> MANTOMAC-CHA (213SCA) | AD31: =Tabela2[[#This Row],[Issue2]]-Tabela2[[#This Row],[Failure2]] -> 90 | AE31: ="FY"&IF(MONTH(Y31)>=4,YEAR(Y31),YEAR(Y31)-1) -> FY2022 | AF31: =YEAR(Tabela2[[#This Row],[Issue2]]) -> 2022
A32: KBISP202211514 | B32: PC130LC-10M0, RADIATOR GROUP, ADAPTADOR, ENTER/LEAKS, | C32: PC130LC-10M0 | D32: B20089 | E32: 716 - Bucket | F32: Bucket clearance | G32: =Tabela2[[#This Row],[Failed Part Name]] -> ADAPTADOR | I32: 512 | J32: Plant.Confirmed | K32: 44883 | M32: 44733 | O32: 6208-51-5410 | P32: ADAPTADOR | Q32: RADIATOR GROUP | R32: ENTER/LEAKS | S32: KDB (Plant) (51) | T32: KDB - Quality Assurance | U32: In Process | V32: 44888 | W32: BAUKO (213SPA) | X32: KBI (9447) | Y32: 44888 | AA32: Luis Siqueira | AB32: 213SPA | AC32: =INDEX('DB Description'!$A$1:$B$23,MATCH(Tabela2[[#This Row],[Filial DB code]],'DB Description'!A:A,),2) -> Bauko | AD32: =Tabela2[[#This Row],[Issue2]]-Tabela2[[#This Row],[Failure2]] -> 5 | AE32: ="FY"&IF(MONTH(Y32)>=4,YEAR(Y32),YEAR(Y32)-1) -> FY2022 | AF32: =YEAR(Tabela2[[#This Row],[Issue2]]) -> 2022
A33: KBISP202211515 | B33: PC130LC-10M0, BUCKET(H/E BACKHOE), BUCKET, BROKEN, | C33: PC130LC-10M0 | D33: B20024 | E33: 716 - Bucket | F33: Bucket clearance | G33: =Tabela2[[#This Row],[Failed Part Name]] -> BUCKET | I33: 1409 | J33: Sub.Received | K33: 44883 | L33: 44883 | M33: 44643 | N33: 44662 | O33: 203-79-B2010 | P33: BUCKET | Q33: BUCKET(H/E BACKHOE) | R33: BROKEN | S33: KDB (Plant) (51) | T33: KBI - Construction Service | U33: In Process | V33: 44889 | W33: BAUKO (213SPA) | X33: KBI (9447) | Y33: 44889 | Z33: A PEÇA VEIO A FRATURAR POR REDUÇÃO NA ÁREA DE ESFORÇO, PROVENIENTE DA PROPAGAÇÃO DA TRINCA. PARA REALIZAR O ENSAIO DE LIQUIDO PENETRANTE, FOI UTILIZADO OS APARAMETROS E PROCESSOS DA NORMA NBR 16450. Cliente novo com Komatsu, primeiro equipamento adiquirido no mes de abril de 2022, cliente com revisoes periodicas na concessionaria. | AA33: Caio Rodrigues | AB33: 213ESD | AC33: =INDEX('DB Description'!$A$1:$B$23,MATCH(Tabela2[[#This Row],[Filial DB code]],'DB Description'!A:A,),2) -> Bauko | AD33: =Tabela2[[#This Row],[Issue2]]-Tabela2[[#This Row],[Failure2]] -> 6 | AE33: ="FY"&IF(MONTH(Y33)>=4,YEAR(Y33),YEAR(Y33)-1) -> FY2022 | AF33: =YEAR(Tabela2[[#This Row],[Issue2]]) -> 2022
A34: KBISP202211516 | B34: PC130LC-10M0, OPERATOR CAB & ROPS, PARTES LATERAIS CINZAS DO PARABRISA, DEFECTIVE APPEARANCE, | C34: PC130LC-10M0 | D34: B20095 | E34: 000 - Machine | F34: Painting | G34: =Tabela2[[#This Row],[Failed Part Name]] -> PARTES LATERAIS CINZAS DO PARABRISA | I34: 404 | J34: Sub.Received | K34: 44887 | L34: 44890 | M34: 44734 | N34: 44776 | O34: NA | P34: PARTES LATERAIS CINZAS DO PARABRISA | Q34: OPERATOR CAB & ROPS | R34: DEFECTIVE APPEARANCE | S34: KDB (Plant) (51) | T34: KBI - Construction Service | U34: In Process | V34: 44890 | W34: BAUKO (213SPA) | X34: KBI (9447) | Y34: 44890 | Z34: Devemos fazer o reparo em garantia. Refazer a pintura. | AA34: Rafaella Ribeiro | AB34: 213SPC | AC34: =INDEX('DB Description'!$A$1:$B$23,MATCH(Tabela2[[#This Row],[Filial DB code]],'DB Description'!A:A,),2) -> Bauko | AD34: =Tabela2[[#This Row],[Issue2]]-Tabela2[[#This Row],[Failure2]] -> 3 | AE34: ="FY"&IF(MONTH(Y34)>=4,YEAR(Y34),YEAR(Y34)-1) -> FY2022 | AF34: =YEAR(Tabela2[[#This Row],[Issue2]]) -> 2022
A35: KBISC202212501 | B35: PC130LC-10M0, HYDRAULIC CYLINDER, ORING, ENTER/LEAKS, VAZAMENTO DE OLEO NO TUBO DO CILINDRO | C35: PC130LC-10M0 | D35: B20154 | E35: 6A0 - Hydraulic piping | F35: Hose leak | G35: VAZAMENTO DE OLEO NO TUBO DO CILINDRO | I35: 91 | J35: Sub.Received | K35: 44888 | L35: 44888 | M35: 44816 | N35: 44837 | O35: 02896-11018 | P35: ORING | Q35: HYDRAULIC CYLINDER | R35: ENTER/LEAKS | S35: KDB (Plant) (51) | T35: KBI - Construction Service | U35: In Process | V35: 44896 | W35: MANTOMAC-CHA (213SCA) | X35: KBI (9447) | Y35: 44896 | Z35: EQUIPAMENTO NOVO COM APENAS 91 HS. | AA35: Luciana Lumbieri | AB35: 213RSB | AC35: =INDEX('DB Description'!$A$1:$B$23,MATCH(Tabela2[[#This Row],[Filial DB code]],'DB Description'!A:A,),2) -> MANTOMAC-CHA (213SCA) | AD35: =Tabela2[[#This Row],[Issue2]]-Tabela2[[#This Row],[Failure2]] -> 8 | AE35: ="FY"&IF(MONTH(Y35)>=4,YEAR(Y35),YEAR(Y35)-1) -> FY2022 | AF35: =YEAR(Tabela2[[#This Row],[Issue2]]) -> 2022
A36: KBISP202212500 | B36: PC130LC-10M0, FUEL TANK GROUP, FILTRO DE COMBUSTÍVEL, MALFUNCTION, | C36: PC130LC-10M0 | D36: B20050 | G36: =Tabela2[[#This Row],[Failed Part Name]] -> FILTRO DE COMBUSTÍVEL | I36: 594 | J36: Sub.Received | K36: 44874 | M36: 44673 | N36: 44727 | O36: 600-311-3620 | P36: FILTRO DE COMBUSTÍVEL | Q36: FUEL TANK GROUP | R36: MALFUNCTION | S36: KDB (Plant) (51) | T36: KBI - Construction Service | U36: In Process | V36: 44896 | W36: BAUKO (213SPA) | X36: KBI (9447) | Y36: 44896 | AA36: Luis Siqueira | AB36: 213SPA | AC36: =INDEX('DB Description'!$A$1:$B$23,MATCH(Tabela2[[#This Row],[Filial DB code]],'DB Description'!A:A,),2) -> Bauko | AD36: =Tabela2[[#This Row],[Issue2]]-Tabela2[[#This Row],[Failure2]] -> 22 | AE36: ="FY"&IF(MONTH(Y36)>=4,YEAR(Y36),YEAR(Y36)-1) -> FY2022 | AF36: =YEAR(Tabela2[[#This Row],[Issue2]]) -> 2022
A37: KBIMB202212501 | B37: PC130LC-10M0, OTHERS, INTERRUPTOR, MALFUNCTION, FALHA ACIONAMENTO BUZINA | C37: PC130LC-10M0 | D37: B20085 | E37: D00 - Electric system | F37: Nozzler malfunction | G37: FALHA ACIONAMENTO BUZINA | I37: 1050 | J37: Sub.Received | K37: 44875 | M37: 44725 | N37: 44763 | O37: 22U-43-21211 | P37: INTERRUPTOR | Q37: OTHERS | R37: MALFUNCTION | S37: KDB (Plant) (51) | T37: KBI - Construction Service | U37: In Process | V37: 44903 | W37: Mason (213I) | X37: KBI (9447) | Y37: 44903 | AA37: Higor Alves | AB37: 213MGC | AC37: =INDEX('DB Description'!$A$1:$B$23,MATCH(Tabela2[[#This Row],[Filial DB code]],'DB Description'!A:A,),2) -> Mason | AD37: =Tabela2[[#This Row],[Issue2]]-Tabela2[[#This Row],[Failure2]] -> 28 | AE37: ="FY"&IF(MONTH(Y37)>=4,YEAR(Y37),YEAR(Y37)-1) -> FY2022 | AF37: =YEAR(Tabela2[[#This Row],[Issue2]]) -> 2022
A38: KBISP202212503 | B38: PC130LC-10M0, RADIATOR GROUP, anticongelante, HIGH/LOW LEVEL, | C38: PC130LC-10M0 | D38: B20144 | E38: 6A0 - Hydraulic piping | F38: Hose leak | G38: =Tabela2[[#This Row],[Failed Part Name]] -> anticongelante | I38: 29 | J38: Plant.QA Approved | K38: 44894 | M38: 44797 | O38: 600-411-1113 | P38: anticongelante | Q38: RADIATOR GROUP | R38: HIGH/LOW LEVEL | S38: KDB (Plant) (51) | T38: KDB - Quality Assurance | U38: In Process | V38: 44903 | W38: BAUKO (213SPA) | X38: KBI (9447) | Y38: 44903 | AA38: Luis Siqueira | AB38: 213SPA | AC38: =INDEX('DB Description'!$A$1:$B$23,MATCH(Tabela2[[#This Row],[Filial DB code]],'DB Description'!A:A,),2) -> Bauko | AD38: =Tabela2[[#This Row],[Issue2]]-Tabela2[[#This Row],[Failure2]] -> 9 | AE38: ="FY"&IF(MONTH(Y38)>=4,YEAR(Y38),YEAR(Y38)-1) -> FY2022 | AF38: =YEAR(Tabela2[[#This Row],[Issue2]]) -> 2022
A39: KBIMB202212503 | B39: PC130LC-10M0, AIR CONDITIONER, HINGE, WELDED, DEFECTIVE APPEARANCE, QUEBRA SUPORTE CONDENSADOR | C39: PC130LC-10M0 | D39: B20085 | E39: 450 - A/C | F39: Condensor support crack | G39: QUEBRA SUPORTE CONDENSADOR | I39: 1050 | J39: Sub.Received | K39: 44875 | M39: 44725 | N39: 44763 | O39: 198-06-62820 | P39: HINGE, WELDED | Q39: AIR CONDITIONER | R39: DEFECTIVE APPEARANCE | S39: KDB (Plant) (51) | T39: KBI - Construction Service | U39: In Process | V39: 44904 | W39: Mason (213I) | X39: KBI (9447) | Y39: 44904 | Z39: Foi efetuado o aperto correto dos parafusos do condensador, porem veio ocasionar a quebra dasolda de fixação da dobradiça | AA39: Higor Alves | AB39: 213MGC | AC39: =INDEX('DB Description'!$A$1:$B$23,MATCH(Tabela2[[#This Row],[Filial DB code]],'DB Description'!A:A,),2) -> Mason | AD39: =Tabela2[[#This Row],[Issue2]]-Tabela2[[#This Row],[Failure2]] -> 29 | AE39: ="FY"&IF(MONTH(Y39)>=4,YEAR(Y39),YEAR(Y39)-1) -> FY2022 | AF39: =YEAR(Tabela2[[#This Row],[Issue2]]) -> 2022
A40: KBISC202212523 | B40: PC130LC-10M0, HYDRAULIC PIPING(1), 00000, MALFUNCTION, DESVIO NO DESLOCAMENTO PARA A DIREITA | C40: PC130LC-10M0 | D40: B20106 | G40: DESVIO NO DESLOCAMENTO PARA A DIREITA | I40: 63 | J40: Plant.QA Approved | K40: 44917 | M40: 44742 | N40: 44894 | O40: 000000 | P40: 00000 | Q40: HYDRAULIC PIPING(1) | R40: MALFUNCTION | S40: KDB (Plant) (51) | T40: KDB - Quality Assurance | U40: In Process | V40: 44918 | W40: MANTOMAC-CHA (213SCA) | X40: KBI (9447) | Y40: 44918 | Z40: EQUIPAMENTO NOVO. | AA40: Luciana Lumbieri | AB40: 213RSB | AC40: =INDEX('DB Description'!$A$1:$B$23,MATCH(Tabela2[[#This Row],[Filial DB code]],'DB Description'!A:A,),2) -> MANTOMAC-CHA (213SCA) | AD40: =Tabela2[[#This Row],[Issue2]]-Tabela2[[#This Row],[Failure2]] -> 1 | AE40: ="FY"&IF(MONTH(Y40)>=4,YEAR(Y40),YEAR(Y40)-1) -> FY2022 | AF40: =YEAR(Tabela2[[#This Row],[Issue2]]) -> 2022
...

Sheet hiddenSheet
A1: incident:IfgMPuVM9DpOp4cIMwns92G4DKTpk7FuObboEQiZdIgBEudOO+dWO3n85WCnwPE8JKSWGKojkYYIT5e58gYWyQ==:incidentid=%28Do%20Not%20Modify%29%20TSR&checksumLogicalName=%28Do%20Not%20Modify%29%20Row%20Checksum&modifiedon=%28Do%20Not%20Modify%29%20Modified%20On&kom_casetype=Case%20Type&kom_reportid=Report%20ID&title=Title&elogic_fullmodel=Full%20Model&elogic_serialnumber=Serial%20Number&kom_titlesuffix=Additional%20Failure%20Description&parentcaseid=Parent%20Case&kom_failuresmr=Failure%20SMR&kom_activestage=Active%20Stage&elogic_failuredate=Failure%20Date&kom_machinemanufacturingdate=Machine%20Manufacturing%20Date&kom_deliverydate=Delivery%20Date&kom_failedpartnumber=Failed%20Part%20Number&kom_failedpartname=Failed%20Part%20Name&kom_componentname_new=Component%20Name&kom_phenomenonname_new=Phenomenon%20Name&kom_factoryplant=Plant&kom_currentqueue=Current%20Queue&statuscode=Status%20Reason&createdon=Created%20On&customerid=Distributor&kom_subsidiaryid=Subsidiary&kom_issuedate=Issue%20Date&kom_submitteddate=Submitted%20Date&kom_additionalnotes=Additional%20Notes%28Request%29&primarycontactid=Distributor%20Contact
A2: TSR | B2: TSI | C2: ETSI | D2: 50 point Inspection | E2: Pre-Delivery Inspection | F2: Component Change Out (Before Failure) | G2: Periodic Maintenance
A3: Created | B3: Approved | C3: Sub.Received | D3: Sub.Submitted | E3: Plant.Confirmed | F3: Plant.Replied | G3: Plant.QA Approved | H3: Sub.Confirmed Reply | I3: OEM HQ.Confirmed Reply | J3: Closed
A4: Information Requested | B4: Parts Return Requested | C4: New | D4: Accepted | E4: Researching | F4: Pending Distributor Feedback | G4: Distributor Feedback Provided | H4: Solution Provided | I4: Cancellation Requested | J4: In Process | K4: Pending Request | L4: Additional action | M4: Problem Solved | N4: Information Provided | O4: Completed | P4: Canceled | Q4: Merged | R4: Rejected - Non-Komatsu Part | S4: Rejected - Incorrect Use of Equipment | T4: Rejected - Duplicate | U4: Disapproved
